<?xml version="1.0" encoding="utf-8"?>
<!-- This URDF was automatically created by SolidWorks to URDF Exporter! Originally created by Stephen Brawner (brawner@gmail.com) 
     Commit Version: 1.6.0-1-g15f4949  Build Version: 1.6.7594.29634
     For more information, please see http://wiki.ros.org/sw_urdf_exporter -->
<robot
  name="rrc_2wheel_robot">
  <link name="base_footprint">
   </link>
  <link
    name="robot_chassis">
    <inertial>
      <origin
        xyz="0.0382 0 0.0125"
        rpy="1.5708 0 0" />
      <mass
        value="0.3" />
      <inertia
        ixx="0.000090506"
        ixy="0"
        ixz="0"
        iyy="0.00045"
        iyz="0"
        izz="0.000360506" />
    </inertial>
    <visual>
      <origin
        xyz="0 0 0"
        rpy="0 0 0" />
      <geometry>
        <mesh
          filename="package://rrc_2wheel_robot/meshes/robot_chassis.STL" />
      </geometry>
      <material
        name="">
        <color
          rgba="0.8 0.1 0.1 1" />
      </material>
    </visual>
    <collision>
      <origin
        xyz="0.0382 0 0.0125"
        rpy="0 0 0" />
      <geometry>
        <box
          size="0.12 0.06 0.0045" />
      </geometry>
    </collision>
  </link>
  <joint 
    name="base_joint" 
    type="fixed">
    <origin
      xyz="0 0 -0.005"
      rpy="0 0 0" />
    <parent 
      link="base_footprint"/>
    <child 
      link="robot_chassis"/>
  </joint>
  
  <link
    name="Left_wheel">
    <inertial>
      <origin
        xyz="1.5739E-05 9.087E-06 -0.0031408"
        rpy="0 0 0" />
      <mass
        value="0.006" />
      <inertia
        ixx="3.6121E-07"
        ixy="6.4607E-11"
        ixz="-6.1593E-11"
        iyy="3.6114E-07"
        iyz="-3.5561E-11"
        izz="6.9454E-07" />
    </inertial>
    <visual>
      <origin
        xyz="0 0 0"
        rpy="0 3.14 0" />
      <geometry>
        <mesh
          filename="package://rrc_2wheel_robot/meshes/Left_wheel.STL" />
      </geometry>
      <material
        name="">
        <color
          rgba="0.29804 0.29804 0.29804 1" />
      </material>
    </visual>
    <collision>
      <origin
        xyz="0 0 0"
        rpy="0 3.14 0" />
      <geometry>
        <mesh
          filename="package://rrc_2wheel_robot/meshes/Left_wheel_collision.STL" />
      </geometry>
    </collision>
  </link>
  <joint
    name="l_wheel_joint"
    type="continuous">
    <origin
      xyz="-0.00018078 0.032511 0.019693"
      rpy="1.5708 0 0" />
    <parent
      link="robot_chassis" />
    <child
      link="Left_wheel" />
    <axis
      xyz="0 0 1" />
    <limit
      effort="0"
      velocity="300" />
  </joint>
  
  <link
    name="Right_wheel">
    <inertial>
      <origin
        xyz="1.5739E-05 9.087E-06 0.0031408"
        rpy="0 0 0" />
      <mass
        value="0.006" />
      <inertia
        ixx="3.6121E-07"
        ixy="6.4607E-11"
        ixz="-6.1593E-11"
        iyy="3.6114E-07"
        iyz="-3.5561E-11"
        izz="6.9454E-07" />
    </inertial>
    <visual>
      <origin
        xyz="0 0 0"
        rpy="0 0 0" />
      <geometry>
        <mesh
          filename="package://rrc_2wheel_robot/meshes/Right_wheel.STL" />
      </geometry>
      <material
        name="">
        <color
          rgba="0.29804 0.29804 0.29804 1" />
      </material>
    </visual>
    <collision>
      <origin
        xyz="0 0 0"
        rpy="0 0 0" />
      <geometry>
        <mesh
          filename="package://rrc_2wheel_robot/meshes/Right_wheel_collision.STL" />
      </geometry>
    </collision>
  </link>
  <joint
    name="r_wheel_joint"
    type="continuous">
    <origin
      xyz="-0.00018078 -0.032511 0.019693"
      rpy="1.5708 0 0" />
    <parent
      link="robot_chassis" />
    <child
      link="Right_wheel" />
    <axis
      xyz="0 0 1" />
    <limit
      effort="0"
      velocity="300" />
  </joint>
  
  <link
    name="Castor_wheel">
    <inertial>
      <origin
        xyz="0 0 0"
        rpy="0 0 0" />
      <mass
        value="0.005" />
      <inertia
        ixx="0"
        ixy="0"
        ixz="0"
        iyy="0"
        iyz="0"
        izz="0" />
    </inertial>
    <visual>
      <origin
        xyz="0 0 0"
        rpy="0 0 0" />
      <geometry>
        <mesh
          filename="package://rrc_2wheel_robot/meshes/Castor_wheel.STL" />
      </geometry>
      <material
        name="">
        <color
          rgba="1 1 1 1" />
      </material>
    </visual>
    <collision>
      <origin
        xyz="0 0 0"
        rpy="0 0 0" />
      <geometry>
        <mesh
          filename="package://rrc_2wheel_robot/meshes/Castor_wheel_collision.STL" />
      </geometry>
    </collision>
  </link>
  <joint
    name="castor_joint"
    type="fixed">
    <origin
      xyz="0.060344 -0.00020036 0.0046825"
      rpy="-1.5895 0.02407 1.6021" />
    <parent
      link="robot_chassis" />
    <child
      link="Castor_wheel" />
    <axis
      xyz="0 0 0" />
  </joint>
  
  <link name="sensor_left">
   </link>
  <joint
    name="L_sensor"
    type="fixed">
    <origin
      xyz="0.054044 0.030189 0.024693"
      rpy="-1.5708 0 0" />
    <parent
      link="robot_chassis" />
    <child
      link="sensor_left" />
    <axis
      xyz="0 0 0" />
  </joint>
  
  <link name="sensor_front">
   </link>
  <joint
    name="F_sensor"
    type="fixed">
    <origin
      xyz="0.084719 6.3686E-05 0.024693"
      rpy="0 1.5708 0" />
    <parent
      link="robot_chassis" />
    <child
      link="sensor_front" />
    <axis
      xyz="0 0 0" />
  </joint>
  
  <link name="sensor_right">
   </link>
  <joint
    name="R_sensor"
    type="fixed">
    <origin
      xyz="0.054044 -0.030611 0.024693"
      rpy="-1.5708 0 3.1416" />
    <parent
      link="robot_chassis" />
    <child
      link="sensor_right" />
    <axis
      xyz="0 0 0" />
  </joint>
</robot>
