<?xml version="1.0"?>
<!-- This URDF was automatically created by SolidWorks to URDF Exporter! Originally created by Stephen Brawner (brawner@gmail.com) 
     Commit Version: 1.6.0-1-g15f4949  Build Version: 1.6.7594.29634
     For more information, please see http://wiki.ros.org/sw_urdf_exporter -->
<robot xmlns:xacro="http://www.ros.org/wiki/xacro" name="rrc_2wheel_robot">

  <!--Color Properties-->
  <material name="blue">
    <color rgba="0 0 0.8 1"/>
  </material>
  <material name="grey">
    <color rgba="0.2 0.2 0.2 1"/>
  </material>
  <material name="orange">
    <color rgba="1.0 0.423529411765 0.0392156862745 1.0"/>
  </material>

  <gazebo reference="robot_chassis">
    <material>Gazebo/Orange</material>
    <turnGravityOff>false</turnGravityOff>
  </gazebo>
  <gazebo reference="Left_wheel">
    <material>Gazebo/Grey</material>
    <turnGravityOff>false</turnGravityOff>
  </gazebo>
  <gazebo reference="Right_wheel">
    <material>Gazebo/Grey</material>
    <turnGravityOff>false</turnGravityOff>
  </gazebo>

  <!--Base footprint ie. main parent link-->
  <link name="base_footprint">
   </link>

  <!--Robot chassis link-->
  <link
    name="robot_chassis">
    <inertial>
      <origin
        xyz="0.0382 0 0.0125"
        rpy="1.5708 0 0" />
      <mass
        value="0.4" />
      <inertia
        ixx="0.000090506"
        ixy="0"
        ixz="0"
        iyy="0.00045"
        iyz="0"
        izz="0.000360506" />
    </inertial>
    <visual>
      <origin
        xyz="0 0 0"
        rpy="0 0 0" />
      <geometry>
        <mesh
          filename="package://rrc_2wheel_robot/meshes/robot_chassis.STL" />
      </geometry>
      <material
        name="orange">
      </material>
    </visual>
    <collision>
      <origin
        xyz="0.0382 0 0.0125"
        rpy="0 0 0" />
      <geometry>
        <box
          size="0.12 0.06 0.0045" />
      </geometry>
    </collision>
  </link>
  <!--base footprint to Robot chassis joint-->
  <joint 
    name="base_footprint_joint" 
    type="fixed">
    <origin
      xyz="0 0 -0.003"
      rpy="0 0 0" />
    <parent 
      link="base_footprint"/>
    <child 
      link="robot_chassis"/>
  </joint>

  <!--Left Wheel link-->
  <link
    name="Left_wheel">
    <inertial>
      <origin
        xyz="1.5739E-05 9.087E-06 -0.0031408"
        rpy="0 0 0" />
      <mass
        value="0.06" />
      <inertia
        ixx="3.6121E-06"
        ixy="6.4607E-10"
        ixz="-6.1593E-10"
        iyy="3.6114E-06"
        iyz="-3.5561E-10"
        izz="6.9454E-06" />
    </inertial>
    <visual>
      <origin
        xyz="0 0 0"
        rpy="0 3.14 0" />
      <geometry>
        <mesh
          filename="package://rrc_2wheel_robot/meshes/Left_wheel.STL" />
      </geometry>
      <material
        name="grey">
      </material>
    </visual>
    <collision>
      <origin
        xyz="0 0 0"
        rpy="0 3.14 0" />
      <geometry>
        <mesh
          filename="package://rrc_2wheel_robot/meshes/Left_wheel_collision.STL" />
      </geometry>
      <!--surface>
        <friction>
          <ode>
            <mu>0</mu>
            <mu2>0</mu2>
            <slip1>1.0</slip1>
            <slip2>1.0</slip2>
          </ode>
        </friction>
      </surface-->
    </collision>
  </link>

  <!--left wheel to Robot chassis joint-->
  <joint
    name="l_wheel_joint"
    type="continuous">
    <origin
      xyz="-0.00018078 0.032511 0.019693"
      rpy="1.5708 0 0" />
    <parent
      link="robot_chassis" />
    <child
      link="Left_wheel" />
    <axis
      xyz="0 0 -1" />
    <limit
      effort="1000"
      velocity="1000" />
    <!--joint_properties 
      damping="1.0" 
      friction="1.0" -->
  </joint>

  <transmission name="l_wheel_joint_trans">
      <type>transmission_interface/SimpleTransmission</type>
      <joint name="l_wheel_joint" />
      <actuator name="$l_wheel_joint_motor">
        <hardwareInterface>EffortJointInterface</hardwareInterface>
        <mechanicalReduction>1</mechanicalReduction>
      </actuator>
    </transmission>

  <gazebo reference="Left_wheel">
    <kp>10000000.0</kp> 
    <kd>100.0</kd>
    <mu1>35.0</mu1>
    <mu2>35.0</mu2>
    <material>Gazebo/Grey</material>
   </gazebo>

  <!--Right Wheel link-->
  <link
    name="Right_wheel">
    <inertial>
      <origin
        xyz="1.5739E-05 9.087E-06 0.0031408"
        rpy="0 0 0" />
      <mass
        value="0.06" />
      <inertia
        ixx="3.6121E-06"
        ixy="6.4607E-10"
        ixz="-6.1593E-10"
        iyy="3.6114E-06"
        iyz="-3.5561E-10"
        izz="6.9454E-06" />
    </inertial>
    <visual>
      <origin
        xyz="0 0 0"
        rpy="0 0 0" />
      <geometry>
        <mesh
          filename="package://rrc_2wheel_robot/meshes/Right_wheel.STL" />
      </geometry>
      <material
        name="grey">
      </material>
    </visual>
    <collision>
      <origin
        xyz="0 0 0"
        rpy="0 0 0" />
      <geometry>
        <mesh
          filename="package://rrc_2wheel_robot/meshes/Right_wheel_collision.STL" />
      </geometry>
      <!--surface>
        <friction>
          <ode>
            <mu>0</mu>
            <mu2>0</mu2>
            <slip1>1.0</slip1>
            <slip2>1.0</slip2>
          </ode>
        </friction>
      </surface-->
    </collision>
  </link>
  
  <!--Right wheel to Robot chassis joint-->
  <joint
    name="r_wheel_joint"
    type="continuous">
    <origin
      xyz="-0.00018078 -0.032511 0.019693"
      rpy="1.5708 0 0" />
    <parent
      link="robot_chassis" />
    <child
      link="Right_wheel" />
    <axis
      xyz="0 0 -1" />
    <limit
      effort="1000"
      velocity="1000" />
    <!--joint_properties 
      damping="1.0" 
      friction="1.0" -->
  </joint>

  <transmission name="r_wheel_joint_trans">
      <type>transmission_interface/SimpleTransmission</type>
      <joint name="r_wheel_joint" />
      <actuator name="$r_wheel_joint_motor">
        <hardwareInterface>EffortJointInterface</hardwareInterface>
        <mechanicalReduction>1</mechanicalReduction>
      </actuator>
    </transmission>

  <gazebo reference="Right_wheel">
    <kp>10000000.0</kp> 
    <kd>100.0</kd>
    <mu1>35.0</mu1>
    <mu2>35.0</mu2>
    <material>Gazebo/Grey</material>
   </gazebo>

  <!--Castor wheel link-->
  <link
    name="Castor_wheel">
    <inertial>
      <origin
        xyz="0 0 0"
        rpy="0 0 0" />
      <mass
        value="0.005" />
      <inertia
        ixx="0"
        ixy="0"
        ixz="0"
        iyy="0"
        iyz="0"
        izz="0" />
    </inertial>
    <visual>
      <origin
        xyz="0 0 0"
        rpy="0 0 0" />
      <geometry>
        <mesh
          filename="package://rrc_2wheel_robot/meshes/Castor_wheel.STL" />
      </geometry>
      <material
        name="">
        <color
          rgba="1 1 1 1" />
      </material>
    </visual>
    <collision>
      <origin
        xyz="0 0 0"
        rpy="0 0 0" />
      <geometry>
        <mesh
          filename="package://rrc_2wheel_robot/meshes/Castor_wheel_collision.STL" />
      </geometry>
      <!--surface>
        <friction>
          <ode>
            <mu>0</mu>
            <mu2>0</mu2>
            <slip1>1.0</slip1>
            <slip2>1.0</slip2>
          </ode>
        </friction>
      </surface-->
    </collision>
  </link>

  <!--Castor wheel to Robot chassis joint-->
  <joint
    name="castor_joint"
    type="fixed">
    <origin
      xyz="0.060344 -0.00020036 0.0046825"
      rpy="-1.5895 0.02407 1.6021" />
    <parent
      link="robot_chassis" />
    <child
      link="Castor_wheel" />
    <axis
      xyz="0 0 0" />
  </joint>

  <!--Left range sensor link-->
  <link name="sonar_left">
   </link>
  <joint
    name="L_sensor"
    type="fixed">
    <origin
      xyz="0.054044 0.030189 0.024693"
      rpy="0 0 1.5708" />
    <parent
      link="robot_chassis" />
    <child
      link="sonar_left" />
    <axis
      xyz="0 0 0" />
  </joint>
      <gazebo reference="sonar_left">
      <sensor type="ray" name="sonar_left_sensor">
        <visualize>true</visualize>
        <update_rate>5</update_rate>
        <ray>
          <scan>
            <horizontal>
              <samples>5</samples>
              <resolution>1.0</resolution>
              <min_angle>-0.1</min_angle>
              <max_angle>0.1</max_angle>
            </horizontal>
            <vertical>
              <samples>5</samples>
              <resolution>1.0</resolution>
              <min_angle>-0.05</min_angle>
              <max_angle>0.05</max_angle>
            </vertical>
          </scan>
          <range>
            <min>0.02</min>
            <max>0.5</max>
            <resolution>0.01</resolution>
          </range>
        </ray>
        <!-- Gazebo-ROS interface plugin -->
        <plugin filename="libgazebo_ros_range.so" name="gazebo_ros_range">
          <gaussianNoise>0.015</gaussianNoise>
          <alwaysOn>true</alwaysOn>
          <updateRate>5</updateRate>
          <topicName>/sonar_l_sensor</topicName>
          <frameName>sonar_left</frameName>
          <fov>0.5</fov>
          <radiation>ultrasound</radiation>
        </plugin>
      </sensor>
    </gazebo>

  <!--Front range sensor link-->
  <link name="sonar_front">
   </link>
  <joint
    name="F_sensor"
    type="fixed">
    <origin
      xyz="0.084719 6.3686E-05 0.024693"
      rpy="0 0 0" />
    <parent
      link="robot_chassis" />
    <child
      link="sonar_front" />
    <axis
      xyz="0 0 0" />
  </joint>
      <gazebo reference="sonar_front">
      <sensor type="ray" name="sonar_front_sensor">
        <visualize>true</visualize>
        <update_rate>5</update_rate>
        <ray>
          <scan>
            <horizontal>
              <samples>5</samples>
              <resolution>1.0</resolution>
              <min_angle>-0.1</min_angle>
              <max_angle>0.1</max_angle>
            </horizontal>
            <vertical>
              <samples>5</samples>
              <resolution>1.0</resolution>
              <min_angle>-0.05</min_angle>
              <max_angle>0.05</max_angle>
            </vertical>
          </scan>
          <range>
            <min>0.02</min>
            <max>0.5</max>
            <resolution>0.01</resolution>
          </range>
        </ray>
        <!-- Gazebo-ROS interface plugin -->
        <plugin filename="libgazebo_ros_range.so" name="gazebo_ros_range">
          <gaussianNoise>0.015</gaussianNoise>
          <alwaysOn>true</alwaysOn>
          <updateRate>5</updateRate>
          <topicName>/sonar_f_sensor</topicName>
          <frameName>sonar_front</frameName>
          <fov>0.5</fov>
          <radiation>ultrasound</radiation>
        </plugin>
      </sensor>
    </gazebo>
  <!--Right range sensor link-->
  <link name="sonar_right">
   </link>
  <joint
    name="R_sensor"
    type="fixed">
    <origin
      xyz="0.054044 -0.030611 0.024693"
      rpy="0 0 -1.5708" />
    <parent
      link="robot_chassis" />
    <child
      link="sonar_right" />
    <axis
      xyz="0 0 0" />
  </joint>
      <gazebo reference="sonar_right">
      <sensor type="ray" name="sonar_right_sensor">
        <visualize>true</visualize>
        <update_rate>5</update_rate>
        <ray>
          <scan>
            <horizontal>
              <samples>5</samples>
              <resolution>1.0</resolution>
              <min_angle>-0.1</min_angle>
              <max_angle>0.1</max_angle>
            </horizontal>
            <vertical>
              <samples>5</samples>
              <resolution>1.0</resolution>
              <min_angle>-0.05</min_angle>
              <max_angle>0.05</max_angle>
            </vertical>
          </scan>
          <range>
            <min>0.02</min>
            <max>0.5</max>
            <resolution>0.01</resolution>
          </range>
        </ray>
        <!-- Gazebo-ROS interface plugin -->
        <plugin filename="libgazebo_ros_range.so" name="gazebo_ros_range">
          <gaussianNoise>0.015</gaussianNoise>
          <alwaysOn>true</alwaysOn>
          <updateRate>5</updateRate>
          <topicName>/sonar_r_sensor</topicName>
          <frameName>sonar_right</frameName>
          <fov>0.5</fov>
          <radiation>ultrasound</radiation>
        </plugin>
      </sensor>
    </gazebo>

  <!-- Differential drive controller  -->
  <gazebo>
    <plugin name="differential_drive_controller" filename="libgazebo_ros_diff_drive.so">

      <rosDebugLevel>Debug</rosDebugLevel>
      <publishWheelTF>true</publishWheelTF>
      <publishOdomTF>true</publishOdomTF>
      <robotNamespace>/</robotNamespace>
      <publishTf>1</publishTf>
      <publishWheelJointState>true</publishWheelJointState>
      <alwaysOn>true</alwaysOn>
      <updateRate>100.0</updateRate>
      <leftJoint>l_wheel_joint</leftJoint>
      <rightJoint>r_wheel_joint</rightJoint>
      <wheelSeparation>0.0646</wheelSeparation>
      <wheelDiameter>0.03412</wheelDiameter>
      <broadcastTF>1</broadcastTF>
      <wheelTorque>20</wheelTorque>
      <wheelAcceleration>2</wheelAcceleration>
      <commandTopic>rrc_2wheel_robot/cmd_vel</commandTopic>
      <odometryFrame>odom</odometryFrame> 
      <odometryTopic>rrc_2wheel_robot/odom</odometryTopic> 
      <robotBaseFrame>base_footprint</robotBaseFrame>

    </plugin>
  </gazebo> 
</robot>
